Workbook

Sheet Dashboard
A1: ITSM Dashboard (IT Asset Guwahati)
C3: Metric | D3: Value | H3: Status | I3: Count | P3: Asset Type | Q3: Count
C4: Total Assets | D4: =COUNTA('Asset Inventory'!A2:A104)/101 -> 1.019802 | H4: Active | I4: =COUNTIF('Asset Inventory'!M:M,"Active") -> 101 | P4: Laptop | Q4: =COUNTIFS('Asset Inventory'!B:B,"Laptop",'Asset Inventory'!M:M,"Active") -> 36
C5: Active Assets | D5: =COUNTIF('Asset Inventory'!M:M,"Active") -> 101 | H5: Repair | I5: =COUNTIF('Asset Inventory'!M:M,"Repair") -> 1 | P5: Desktop | Q5: =COUNTIFS('Asset Inventory'!B:B,"Desk Top",'Asset Inventory'!M:M,"Active") -> 44
C6: Repair Assets | D6: =COUNTIF('Asset Inventory'!M:M,"Repair") -> 1 | H6: Retired | I6: =COUNTIF('Asset Inventory'!M:M,"Retired") -> 0 | P6: Printer | Q6: =COUNTIFS('Asset Inventory'!B:B,"Printer",'Asset Inventory'!M:M,"Active") -> 18
H7: No Stock | I7: =COUNTIF('Asset Inventory'!M:M,"No Stock") -> 1 | P7: Server | Q7: =COUNTIFS('Asset Inventory'!B:B,"Server",'Asset Inventory'!M:M,"Active") -> 3
H8: In Stock | I8: =COUNTIF('Asset Inventory'!M:M,"In Stock") -> 0
B24: Total Tickets | C24: Open Tickets | D24: Closed Tickets | E24: Hold | G24: Incidents | H24: Up | I24: Down | J24: Critical | Q24: Status | R24: Count
B25: =COUNTA(Tickets!A:A)-1 -> 78 | C25: =COUNTIF( Tickets!E:E,"Open") -> 10 | D25: =COUNTIF(Tickets!E:E,"Closed") -> 39 | E25: =COUNTIF(Tickets!E:E,"Hold") -> 5 | G25: =COUNTA(Incidents!A2:A988) -> 3 | H25: =COUNTIF(Incidents!D2:D1000,"Down") -> 1 | I25: =COUNTIF(Incidents!D2:D1000,"Up") -> 2 | J25: =COUNTIF(Incidents!C2:D1000,"Critical") -> 1 | Q25: Open | R25: =COUNTIF(Tickets!E:E,"Open") -> 10
Q26: Closed | R26: =COUNTIF(Tickets!E:E,"Closed") -> 39
Q27: Hold | R27: =COUNTIF(Tickets!E:E,"Hold") -> 5

Sheet Asset Inventory
A1: Asset ID | B1: Asset Type | C1: Asset Name | D1: Brand | E1: Model | F1: Serial No | G1: Employee ID | H1: User Name | I1: Department | J1: Location | K1: Purchase Date | L1: Warranty Expiry | M1: Status | N1: Priority | O1: Remarks
A2: GHY-LAP-0001 | B2: Laptop | C2: Lenovo | D2: Lenovo | E2: E14 | F2: PG-05E2HB | G2: NA | H2: N.P. Singh | I2: Administration | J2: Guwahati | K2: 46006 | L2: 47101 | M2: Active | N2: High
A3: GHY-LAP-0002 | B3: Laptop | C3: Lenovo | D3: Lenovo | E3: E14 | F3: PG-05E2K0 | G3: CPLY143 | H3: Dinesh Sharma | I3: DESPATCH | J3: Guwahati | K3: 46006 | L3: 47101 | M3: Active | N3: High
A4: GHY-LAP-0003 | B4: Laptop | C4: Lenovo | D4: Lenovo | E4: E14 | F4: PG-05E2JJ | G4: CPLY192 | H4: Bijit Sengupta | I4: ACCOUNTS | J4: Guwahati | K4: 46006 | L4: 47101 | M4: Active | N4: High
A5: GHY-LAP-0004 | B5: Laptop | C5: Lenovo | D5: Lenovo | E5: E14 | F5: PG-05E2QD | G5: CPLY698 | H5: Sitansu Sekhar Das | I5: Purchase | J5: Guwahati | K5: 46006 | L5: 47101 | M5: Active | N5: High
A6: GHY-LAP-0005 | B6: Laptop | C6: Lenovo | D6: Lenovo | E6: E14 | F6: PG-05E2Q5 | G6: CPLY920 | H6: Shiba Nunia | I6: MAINTENANCE | J6: Guwahati | K6: 46006 | L6: 47101 | M6: Active | N6: High
A7: GHY-LAP-0006 | B7: Laptop | C7: Lenovo | D7: Lenovo | E7: E14 | F7: PG-05E20A | G7: CPLY726 | H7: Ankur Kalita | I7: ACCOUNTS | J7: Guwahati | K7: 46006 | L7: 47101 | M7: Active | N7: High
A8: GHY-LAP-0007 | B8: Laptop | C8: Lenovo | D8: Lenovo | E8: E14 | F8: PG-05E20H | G8: CPLY715 | H8: Om Bahadur Chetri | I8: HR | J8: Guwahati | K8: 46006 | L8: 47101 | M8: Active | N8: High
A9: GHY-LAP-0008 | B9: Laptop | C9: Lenovo | D9: Lenovo | E9: E14 | F9: PG-05E2GS | G9: PTI139 | H9: Dhanmani Kalita | I9: ACCOUNTS | J9: Guwahati | K9: 46006 | L9: 47101 | M9: Active | N9: High
A10: GHY-LAP-0009 | B10: Laptop | C10: Lenovo | D10: Lenovo | E10: E14 | F10: PG-05E2JF | G10: CPLY1011 | H10: Ajit Kumar Singh | I10: Store | J10: Guwahati | K10: 46006 | L10: 47101 | M10: Active | N10: High
A11: GHY-LAP-0010 | B11: Laptop | C11: Lenovo | D11: Lenovo | E11: E14 | F11: PG-05E2KQ | G11: CPLY971 | H11: Kartik Singh | I11: ACCOUNTS | J11: Guwahati | K11: 46006 | L11: 47101 | M11: Active | N11: High
A12: GHY-LAP-0011 | B12: Laptop | C12: Lenovo | D12: Lenovo | E12: E14 | F12: PG-05E2JT | G12: PTI405 | H12: Alpona Barua | I12: Quality Control | J12: Guwahati | K12: 46006 | L12: 47101 | M12: Active | N12: High
A13: GHY-LAP-0012 | B13: Laptop | C13: Lenovo | D13: Lenovo | E13: E14 | F13: PG-05E2HL | G13: CPLY590 | H13: Gitima Kalita Kumari | I13: ACCOUNTS | J13: Guwahati | K13: 46006 | L13: 47101 | M13: Active | N13: High
... A15: GHY-LAP-0014 | B15: Laptop | C15: Dell | D15: Dell | E15: Inspiron 15 | F15: 6SS9NS3 | G15: PTI384 | H15: Angshu Pronit Mahanta | I15: MAINTENANCE | J15: Guwahati | K15: 46006 | L15: 47101 | M15: Active | N15: High
A16: GHY-LAP-0015 | B16: Laptop | C16: HP | D16: HP | E16: 14S | F16: 5CD1371NN5 | G16: PTI124 | H16: Sonmoni Kalita | I16: HR | J16: Guwahati | K16: 44503 | L16: November 02, 2022 | M16: Active | N16: High
A17: GHY-LAP-0016 | B17: Laptop | C17: Dell | D17: Dell | E17: Insprion15 | F17: G4RDCZ3 | G17: PTI348 | H17: Jintu Moni Das | I17: ACCOUNTS | J17: Guwahati | M17: Active | N17: High
A18: GHY-LAP-0017 | B18: Laptop | C18: HP | D18: HP | E18: 255G8 | F18: CND11367TD | G18: PTI249 | H18: Rakesh Bordoloi | I18: HR | J18: Guwahati | K18: 44321 | L18: May 04, 2022 | M18: Active | N18: High
A19: GHY-LAP-0018 | B19: Laptop | C19: HP | D19: HP | E19: 255G8 | F19: CND11366WW | G19: PTI188 | H19: Partha Pratim Thakuria | I19: HR | J19: Guwahati | M19: Active | N19: High
A20: GHY-LAP-0019 | B20: Laptop | C20: Dell | D20: Dell | E20: Inspiron5559 | F20: BYMNLC2 | G20: CPLY1019 | H20: Bablu Karmakar | I20: IT | J20: Guwahati | K20: September 8, 2016 | L20: September 10, 2017 | M20: No Stock | N20: High
A21: GHY-LAP-0020 | B21: Laptop | C21: Dell | D21: Dell | E21: Inspiron14 7430 | F21: 1BKXLX3 | G21: CPLY1 | H21: Yogesh Kumar Chaudhry | I21: Administration | J21: Guwahati | K21: December 19, 2023 | L21: June 4, 2025 | M21: Active | N21: High
A22: GHY-LAP-0021 | B22: Laptop | C22: Dell | D22: Dell | E22: Optiplex 5000 | F22: H3VPN04 | G22: CPLY78 | H22: Dibyajyoti Bhatta | I22: HR | J22: Guwahati | M22: Active | N22: High
A23: GHY-LAP-0022 | B23: Laptop | C23: Dell | D23: Dell | E23: Inspiron15 3511 | F23: 89N2KY3 | G23: CPLY866 | H23: Durga Madhav Panigrahi | I23: Quality Control | J23: Guwahati | K23: June 28, 2023 | L23: December 20, 2024 | M23: Active | N23: High
A24: GHY-LAP-0023 | B24: Laptop | C24: Hp | D24: Hp | E24: 15s | F24: 5CD137L0WB | G24: CPLY94 | H24: Rohit Kumar Verma | I24: ACCOUNTS | J24: Guwahati | M24: Active | N24: High
A25: GHY-LAP-0024 | B25: Laptop | C25: HP | D25: HP | E25: 15S | F25: 5CD1055H9Q | G25: CPLY192 | H25: Bijit Sengupta | I25: ACCOUNTS | J25: Guwahati | M25: Active | N25: High
A26: GHY-LAP-0025 | B26: Laptop | C26: Dell | D26: Dell | E26: Latitude3400 | F26: JX43003 | G26: CPLY590 | H26: Gitima Kalita Kumari | I26: ACCOUNTS | J26: Guwahati | M26: Active | N26: High
A27: GHY-LAP-0026 | B27: Laptop | C27: HP | D27: HP | E27: 14S | F27: 5CD1371NQ5 | G27: CPLY963 | H27: Suraj Sharma | I27: MAINTENANCE | J27: Guwahati | M27: Active | N27: High
A28: GHY-LAP-0027 | B28: Laptop | C28: Dell | D28: Dell | E28: Inspiron15 3520 | F28: HH05524 | G28: PTI164 | H28: Pallab Das | I28: ACCOUNTS | J28: Guwahati | K28: February 22, 2024 | L28: October 26, 2025 | M28: Active | N28: High
A29: GHY-LAP-0028 | B29: Laptop | C29: Hp | D29: Hp | E29: 250G9 | F29: CND3112340 | G29: PTI238 | H29: Debajit Kalita | I29: MAINTENANCE | J29: Guwahati | M29: Active | N29: High
A30: GHY-LAP-0029 | B30: Laptop | C30: Dell | D30: Dell | E30: Inspiron15 3530 | F30: GHMD554 | G30: PTI39 | H30: Monoj Kumar Choudhury | I30: MAINTENANCE | J30: Guwahati | K30: August 19, 2024 | L30: April 26, 2026 | M30: Active | N30: High
A31: GHY-LAP-0030 | B31: Laptop | C31: Dell | D31: Dell | E31: Inspiron15 3511 | F31: 2B7F5W3 | G31: CPLY170 | H31: Narender Singh | I31: Production | J31: Guwahati | K31: March 29, 2023 | L31: July 18, 2024 | M31: Active | N31: High
A32: GHY-LAP-0031 | B32: Laptop | C32: Lenovo | D32: Lenovo | E32: E14 | F32: PG-05E2JJ | G32: NA | H32: IT room | J32: Guwahati | M32: Active | N32: High
A33: GHY-LAP-0032 | B33: Laptop | C33: Dell | D33: Dell | E33: LATITUDE5310 | F33: 7XF1ZZ2 | G33: NA | H33: IT | J33: Guwahati | M33: Active | N33: High
A34: GHY-LAP-0033 | B34: Laptop | C34: Hp | D34: Hp | E34: 15S | F34: 5CD2100Y91 | G34: NA | H34: IT | J34: Guwahati | K34: May 03, 2022 | L34: May 02, 2023 | M34: Active | N34: High
A35: GHY-LAP-0034 | B35: Laptop | C35: Dell | D35: Dell | E35: Optiplex 3000 | F35: 1XHJ8Y3 | G35: CPLY921 | H35: Neeraj Kumar | I35: Production | J35: Guwahati | M35: Active | N35: High
A36: GHY-LAP-0035 | B36: Laptop | C36: Dell | D36: Dell | E36: Latitute3450 | F36: 1NTTY32 | G36: PTI51 | H36: Amit Kumar Singh | I36: Store | J36: Guwahati | M36: Active | N36: High
A37: GHY-LAP-0036 | B37: Laptop | C37: HP | D37: HP | E37: 240 G4 | F37: 5CG5492LFJ | G37: NA | H37: IT | J37: Guwahati | M37: Active | N37: High
A38: GHY-LAP-0037 | B38: Laptop | C38: Lenovo | D38: Lenovo | E38: E14 | F38: PG05E2JY | G38: CPLY1016 | H38: Aswini Kumar Nayak | I38: HR | J38: Guwahati | K38: 46160 | L38: 47255 | M38: Active | N38: High
A39: GHY-DESK-0001 | B39: Desk Top | C39: Dell | D39: Dell | E39: Optiplex 5000 | F39: 5CD137L0WB | G39: CPLY744 | H39: Ankur Jyoti Das | I39: HR | J39: Guwahati | M39: Active | N39: High
A40: GHY-DESK-0002 | B40: Desk Top | C40: Dell | D40: Dell | E40: Optiplex 3000 | F40: 5CD1055H9Q | G40: NA | H40: Time Office | J40: Guwahati | M40: Active | N40: High
A41: GHY-DESK-0003 | B41: Desk Top | C41: Dell | D41: Dell | E41: Vostro 3800 | F41: CO91P24 | G41: NA | H41: Mohan | J41: Guwahati | K41: April 1, 2014 | L41: July 2, 2017 | M41: Active | N41: High
...

Sheet Warranty Tracker
A1: Asset ID | B1: Warranty Expiry | C1: Days Remaining
A2: CPG-001 | B2: 47101 | C2: =B2-TODAY() -> 897
A3: CPG-002 | B3: 47101 | C3: =B3-TODAY() -> 897
A4: CPG-003 | B4: 47101 | C4: =B4-TODAY() -> 897
A5: CPG-004 | B5: 47101 | C5: =B5-TODAY() -> 897
A6: CPG-005 | B6: 47101 | C6: =B6-TODAY() -> 897
A7: CPG-006 | B7: 47101 | C7: =B7-TODAY() -> 897
A8: CPG-007 | B8: 47101 | C8: =B8-TODAY() -> 897
A9: CPG-008 | B9: 47101 | C9: =B9-TODAY() -> 897
A10: CPG-009 | B10: 47101 | C10: =B10-TODAY() -> 897
A11: CPG-010 | B11: 47101 | C11: =B11-TODAY() -> 897
A12: CPG-011 | B12: 47101 | C12: =B12-TODAY() -> 897
A13: CPG-012 | B13: 47101 | C13: =B13-TODAY() -> 897
A14: CPG-013 | B14: 47101 | C14: =B14-TODAY() -> 897
A15: CPG-014 | C15: =B15-TODAY() -> -46204
A16: CPG-015 | C16: =B16-TODAY() -> -46204
A17: CPG-016 | C17: =B17-TODAY() -> -46204
A18: CPG-017 | C18: =B18-TODAY() -> -46204
A19: CPG-018 | C19: =B19-TODAY() -> -46204
A20: CPG-019 | C20: =B20-TODAY() -> -46204
A21: CPG-020 | C21: =B21-TODAY() -> -46204
A22: CPG-021 | B22: 45944 | C22: =B22-TODAY() -> -260
A23: CPG-022 | C23: =B23-TODAY() -> -46204
A24: CPG-023 | C24: =B24-TODAY() -> -46204
A25: CPG-024 | B25: 45944 | C25: =B25-TODAY() -> -260
A26: CPG-025 | C26: =B26-TODAY() -> -46204
A27: CPG-026 | C27: =B27-TODAY() -> -46204
A28: CPG-027 | C28: =B28-TODAY() -> -46204
A29: CPG-028 | C29: =B29-TODAY() -> -46204
A30: CPG-029 | C30: =B30-TODAY() -> -46204
A31: CPG-030 | C31: =B31-TODAY() -> -46204
A32: CPG-031 | C32: =B32-TODAY() -> -46204
A33: CPG-032 | C33: =B33-TODAY() -> -46204
A34: CPG-033 | C34: =B34-TODAY() -> -46204
A35: CPG-034 | C35: =B35-TODAY() -> -46204
A36: CPG-035 | C36: =B36-TODAY() -> -46204
A37: CPG-036 | C37: =B37-TODAY() -> -46204
... A91: CPG-090 | C91: =B91-TODAY() -> -46204
A92: CPG-091 | B92: 43338 | C92: =B92-TODAY() -> -2866
A93: CPG-092 | B93: 43338 | C93: =B93-TODAY() -> -2866
...

Sheet Tickets
A1: Ticket ID | B1: Date | C1: Category | D1: Priority | E1: Status | F1: Assigned To | H1: Remarks
A2: CPY0001 | B2: 46188 | C2: Implementation Data Centre/NOC | D2: High | E2: Hold | F2: Bablu Karmakar/Nayan moni Das | G2: Sitansu Das | H2: Pending due to civil work not done.
A3: CPY0002 | B3: 46188 | C3: Requested mouse to Production Office | D3: Medium | E3: Closed | F3: Nayan moni Das | G3: Dipjyoti kalita
A4: CPY0003 | B4: 46188 | C4: Requested mouse ped to HR Department | D4: Low | E4: Closed | F4: Nayan moni Das | G4: Aswani Nayak
A5: CPY0004 | B5: 16-06.2026 | C5: Requested to provide the structure diagram | D5: High | E5: Closed | F5: Bablu Karmakar/Nayan moni Das | G5: Sitansu Das | H5: Digram handed over and as discussed the work will be start after two days. 19/06/2026
A6: CPY0005 | B6: 17.06.2026 | C6: Wifi Installed at Training Hall | D6: High | E6: Closed | F6: Nayan moni Das | G6: Training Hall
A7: CPY0006 | B7: 17.06.2026 | C7: Desktop Not Turning on | D7: Medium | E7: Closed | F7: Nayan moni Das | G7: Pallab Das
A8: CPY0007 | B8: 17.06.2026 | C8: Security Gate Camera not working | D8: High | E8: Closed | F8: Nayan moni Das | G8: Security
A9: CPY0008 | B9: 17.06.2026 | C9: Boiler camera not working | D9: High | E9: Closed | F9: Nayan moni Das | G9: Boiler
A10: CPY0009 | B10: 46190 | C10: Power Distibution diagram in DC | D10: High | E10: Closed | F10: Bablu Karmakar | G10: Electrical Department | H10: Diagram completed
A11: CPY0010 | B11: 46190 | C11: Convert the RF link to Fiber (JIO) | D11: Medium | E11: Hold | F11: Bablu Karmakar | G11: Priya Ghosh | H11: As discussed, they will check the feasibility and provide confirmation.
A12: CPY0011 | B12: 46190 | C12: Convert the RF link to Fiber (Ishan 100) | D12: Medium | E12: Hold | F12: Bablu Karmakar | G12: Ankita Mukherjee/Atanu Das | H12: Mail request Correcpending pending .
A13: CPY0012 | B13: 46190 | C13: Power distribution in DC Work | D13: High | E13: Open | F13: Bablu Karmakar/Nayan Das | G13: Electrical Department | H13: Discussion pending with electrical department.
A14: CPY0013 | B14: 46191 | C14: Power diagram submitted for confirmation | D14: High | E14: Hold | F14: Bablu Karmakar / Nayan das | G14: Electrical Department | H14: Material confirmation will be give on Monday.
A15: CPY0014 | B15: 46191 | C15: Printer issue in production | D15: High | E15: Closed | F15: Bablu Karmakar/Nayan Das | G15: Production | H15: Issue in Network . Resolved.
A16: CPY0015 | B16: 46191 | C16: Asset accountablity | D16: High | E16: Closed | F16: Bablu Karmakar/Nayan Das | G16: Ganesh Shaha | H16: Serial no pending.
A17: CPY0016 | B17: 46191 | C17: Camera Issue | D17: High | E17: Closed | F17: Nayan Das | G17: GM Sir | H17: Issue in Dasktop .
A18: CPY0017 | B18: 46191 | C18: Tranning Hall | D18: High | E18: Closed | F18: Nayan Das | G18: GM Sir | H18: Projector to be connect.
A19: CPY0018 | B19: 46192 | C19: Mac address of Laptop, Desk Top Printer | D19: High | E19: Open | F19: Nayan/ Bablu | G19: Nayan and Bablu | H19: Remaining 30no which will be done tomorrow.
A20: CPY0019 | B20: 46192 | C20: Printer not working | D20: Medium | E20: Closed | F20: Nayan Das | G20: Account | H20: Completed
A21: CPY0020 | B21: 46192 | C21: Printer not working | D21: Medium | E21: Closed | F21: Nayan Das | G21: HR | H21: Completed
... A55: CPY0054 | B55: 46202 | C55: PDF Editing issue | D55: Low | E55: Closed | F55: Nayan Das | G55: Jayanta Goswami | H55: PDF converting done
A56: CPY0055
A57: CPY0056
A58: CPY0057
A59: CPY0058
A60: CPY0059
A61: CPY0060
A62: CPY0061
A63: CPY0062
A64: CPY0063
A65: CPY0064
A66: CPY0065
A67: CPY0066
... A79: CPY0078

Sheet Incidents
A1: Incident ID | B1: Date | C1: Severity | D1: Status | E1: Reason
A2: GHY-0001 | B2: 46197 | C2: Critical | D2: Down | E2: Printer head issue
A3: GHY-0002 | B3: 46197 | C3: High | D3: Up | E3: System Working slow need to be upgrade
A4: GHY-0003 | B4: 46197 | C4: High | D4: Up | E4: Licence need to be renew.

Sheet Tag Details
A1: Tag No | B1: Location | C1: Rack No | D1: I/O Box No | E1: Device Connected | F1: Status
A2: GHY-R01-IO01 | B2: Guwahati DC | C2: R01 | D2: IO01 | E2: Core Switch | F2: Active
A3: GHY-R01-IO02 | B3: Guwahati DC | C3: R01 | D3: IO02 | E3: Firewall | F3: Active
A4: GHY-R02-IO01 | B4: Guwahati DC | C4: R02 | D4: IO01 | E4: Server Rack | F4: Active

Sheet Asset Register
A1: Asset Register Format
A2: Asset Tag | B2: QR Code | C2: Bar Code | D2: Asset Name | E2: Make | F2: Model | G2: EMP ID | H2: User | I2: Employee Department | J2: Designation | K2: Employee Grade | L2: Location | M2: Serial No
A3: Laptop
A4: GHY-LAP-0001 | C4: ="*"&A4&"*" -> *GHY-LAP-0001* | D4: Laptop | E4: Lenovo | F4: E14 | G4: NA | H4: N.P. Singh | I4: Administration | J4: Plant Head | L4: Guwahati | M4: PG-05E2HB
A5: GHY-LAP-0002 | C5: ="*"&A5&"*" -> *GHY-LAP-0002* | D5: Laptop | E5: Lenovo | F5: E14 | G5: CPLY143 | H5: Dinesh Sharma | I5: DESPATCH | J5: Sr. Manager- Despatch | L5: Guwahati | M5: PG-05E2K0
A6: GHY-LAP-0003 | C6: ="*"&A6&"*" -> *GHY-LAP-0003* | D6: Laptop | E6: Lenovo | F6: E14 | G6: CPLY192 | H6: Bijit Sengupta | I6: ACCOUNTS | J6: Sr. Manager- Accounts | L6: Guwahati | M6: PG-05E2JJ
A7: GHY-LAP-0004 | C7: ="*"&A7&"*" -> *GHY-LAP-0004* | D7: Laptop | E7: Lenovo | F7: E14 | G7: CPLY698 | H7: Sitansu Sekhar Das | I7: Purchase | J7: Sr. Manager- Purchase | L7: Guwahati | M7: PG-05E2QD
A8: GHY-LAP-0005 | C8: ="*"&A8&"*" -> *GHY-LAP-0005* | D8: Laptop | E8: Lenovo | F8: E14 | G8: CPLY920 | H8: Shiba Nunia | I8: MAINTENANCE | J8: ASSISTANT MANAGER MAINTENANCE | L8: Guwahati | M8: PG-05E2Q5
A9: GHY-LAP-0006 | C9: ="*"&A9&"*" -> *GHY-LAP-0006* | D9: Laptop | E9: Lenovo | F9: E14 | G9: CPLY726 | H9: Ankur Kalita | I9: ACCOUNTS | J9: ACCOUNTS OFFICER | L9: Guwahati | M9: PG-05E20A
A10: GHY-LAP-0007 | C10: ="*"&A10&"*" -> *GHY-LAP-0007* | D10: Laptop | E10: Lenovo | F10: E14 | G10: CPLY715 | H10: Om Bahadur Chetri | I10: HR | J10: Sr. Manager- HR cum LWO | L10: Guwahati | M10: PG-05E20H
A11: GHY-LAP-0008 | C11: ="*"&A11&"*" -> *GHY-LAP-0008* | D11: Laptop | E11: Lenovo | F11: E14 | G11: PTI139 | H11: Dhanmani Kalita | I11: ACCOUNTS | J11: ACCOUNTS EXECUTIVE | L11: Guwahati | M11: PG-05E2GS
A12: GHY-LAP-0009 | C12: ="*"&A12&"*" -> *GHY-LAP-0009* | D12: Laptop | E12: Lenovo | F12: E14 | G12: CPLY1011 | H12: Ajit Kumar Singh | I12: Store | J12: Store Manager | L12: Guwahati | M12: PG-05E2JF
A13: GHY-LAP-0010 | C13: ="*"&A13&"*" -> *GHY-LAP-0010* | D13: Laptop | E13: Lenovo | F13: E14 | G13: CPLY971 | H13: Kartik Singh | I13: ACCOUNTS | J13: ACCOUNTS EXECUTIVE | L13: Guwahati | M13: PG-05E2KQ
A14: GHY-LAP-0011 | C14: ="*"&A14&"*" -> *GHY-LAP-0011* | D14: Laptop | E14: Lenovo | F14: E14 | G14: PTI405 | H14: Alpona Barua | I14: Quality Control | J14: Asstt Manager- Quality Control | L14: Guwahati | M14: PG-05E2JT
A15: GHY-LAP-0012 | C15: ="*"&A15&"*" -> *GHY-LAP-0012* | D15: Laptop | E15: Lenovo | F15: E14 | G15: CPLY590 | H15: Gitima Kalita Kumari | I15: ACCOUNTS | J15: ACCOUNTS EXECUTIVE | L15: Guwahati | M15: PG-05E2HL
... A17: GHY-LAP-0014 | C17: ="*"&A17&"*" -> *GHY-LAP-0014* | D17: Laptop | E17: Dell | F17: Inspiron 15 | G17: PTI384 | H17: Angshu Pronit Mahanta | I17: MAINTENANCE | J17: ASSISTANT MANAGER MAINTENANCE | L17: Guwahati | M17: 6SS9NS3
A18: GHY-LAP-0015 | C18: ="*"&A18&"*" -> *GHY-LAP-0015* | D18: Laptop | E18: HP | F18: 14S | G18: PTI124 | H18: Sonmoni Kalita | I18: HR | J18: OFFICER - HR & ADMIN | L18: Guwahati | M18: 5CD1371NN5 | N18: November 03, 2021 | O18: November 02, 2022
A19: GHY-LAP-0016 | C19: ="*"&A19&"*" -> *GHY-LAP-0016* | D19: Laptop | E19: Dell | F19: Insprion15 | G19: PTI348 | H19: Jintu Moni Das | I19: ACCOUNTS | J19: Trainee | L19: Guwahati | M19: G4RDCZ3
A20: GHY-LAP-0017 | C20: ="*"&A20&"*" -> *GHY-LAP-0017* | D20: Laptop | E20: HP | F20: 255G8 | G20: PTI249 | H20: Rakesh Bordoloi | I20: HR | J20: HR EXECUTIVE | L20: Guwahati | M20: CND11367TD | N20: May 05, 2021 | O20: May 04, 2022
A21: GHY-LAP-0018 | C21: ="*"&A21&"*" -> *GHY-LAP-0018* | D21: Laptop | E21: HP | F21: 255G8 | G21: PTI188 | H21: Partha Pratim Thakuria | I21: HR | J21: Senior Officer-HR | L21: Guwahati | M21: CND11366WW
A22: GHY-LAP-0019 | C22: ="*"&A22&"*" -> *GHY-LAP-0019* | D22: Laptop | E22: Dell | F22: Inspiron5559 | G22: CPLY1019 | H22: Bablu Karmakar | I22: IT | J22: IT-Manager | L22: Guwahati | M22: BYMNLC2 | N22: September 8, 2016 | O22: September 10, 2017
A23: GHY-LAP-0020 | C23: ="*"&A23&"*" -> *GHY-LAP-0020* | D23: Laptop | E23: Dell | F23: Inspiron14 7430 | G23: CPLY1 | H23: Yogesh Kumar Chaudhry | I23: Administration | J23: Unit Head | L23: Guwahati | M23: 1BKXLX3 | N23: December 19, 2023 | O23: June 4, 2025
A24: GHY-LAP-0021 | C24: ="*"&A24&"*" -> *GHY-LAP-0021* | D24: Laptop | E24: Dell | F24: Optiplex 5000 | G24: CPLY78 | H24: Dibyajyoti Bhatta | I24: HR | J24: Dy.Manager- HR | L24: Guwahati | M24: H3VPN04
A25: GHY-LAP-0022 | C25: ="*"&A25&"*" -> *GHY-LAP-0022* | D25: Laptop | E25: Dell | F25: Inspiron15 3511 | G25: CPLY866 | H25: Durga Madhav Panigrahi | I25: Quality Control | J25: Sr. Manager- QC | L25: Guwahati | M25: 89N2KY3 | N25: June 28, 2023 | O25: December 20, 2024
A26: GHY-LAP-0023 | C26: ="*"&A26&"*" -> *GHY-LAP-0023* | D26: Laptop | E26: Hp | F26: 15s | G26: CPLY94 | H26: Rohit Kumar Verma | I26: ACCOUNTS | J26: Plant Commercial Head | L26: Guwahati | M26: 5CD137L0WB
A27: GHY-LAP-0024 | C27: ="*"&A27&"*" -> *GHY-LAP-0024* | D27: Laptop | E27: HP | F27: 15S | G27: CPLY192 | H27: Bijit Sengupta | I27: ACCOUNTS | J27: Sr. Manager- Accounts | L27: Guwahati | M27: 5CD1055H9Q
A28: GHY-LAP-0025 | C28: ="*"&A28&"*" -> *GHY-LAP-0025* | D28: Laptop | E28: Dell | F28: Latitude3400 | G28: CPLY590 | H28: Gitima Kalita Kumari | I28: ACCOUNTS | J28: ACCOUNTS EXECUTIVE | L28: Guwahati | M28: JX43003
A29: GHY-LAP-0026 | C29: ="*"&A29&"*" -> *GHY-LAP-0026* | D29: Laptop | E29: HP | F29: 14S | G29: CPLY963 | H29: Suraj Sharma | I29: MAINTENANCE | J29: DY. MANAGER - MAINTENANCE | L29: Guwahati | M29: 5CD1371NQ5
A30: GHY-LAP-0027 | C30: ="*"&A30&"*" -> *GHY-LAP-0027* | D30: Laptop | E30: Dell | F30: Inspiron15 3520 | G30: PTI164 | H30: Pallab Das | I30: ACCOUNTS | J30: DISPATCH EXECUTIVE | L30: Guwahati | M30: HH05524 | N30: February 22, 2024 | O30: October 26, 2025
A31: GHY-LAP-0028 | C31: ="*"&A31&"*" -> *GHY-LAP-0028* | D31: Laptop | E31: Hp | F31: 250G9 | G31: PTI238 | H31: Debajit Kalita | I31: MAINTENANCE | J31: ELECTRICAL ENGINEER | L31: Guwahati | M31: CND3112340
A32: GHY-LAP-0029 | C32: ="*"&A32&"*" -> *GHY-LAP-0029* | D32: Laptop | E32: Dell | F32: Inspiron15 3530 | G32: PTI39 | H32: Monoj Kumar Choudhury | I32: MAINTENANCE | J32: CHIEF MANAGER- ENGINEERING | L32: Guwahati | M32: GHMD554 | N32: August 19, 2024 | O32: April 26, 2026
A33: GHY-LAP-0030 | C33: ="*"&A33&"*" -> *GHY-LAP-0030* | D33: Laptop | E33: Dell | F33: Inspiron15 3511 | G33: CPLY170 | H33: Narender Singh | I33: Production | J33: DGM (WORKS) | L33: Guwahati | M33: 2B7F5W3 | N33: March 29, 2023 | O33: July 18, 2024
A34: GHY-LAP-0031 | C34: ="*"&A34&"*" -> *GHY-LAP-0031* | D34: Laptop | E34: Lenovo | F34: E14 | G34: NA | H34: IT room | L34: Guwahati | M34: PG-05E2JJ
A35: GHY-LAP-0032 | C35: ="*"&A35&"*" -> *GHY-LAP-0032* | D35: Laptop | E35: Dell | F35: LATITUDE5310 | G35: NA | H35: IT | L35: Guwahati | M35: 7XF1ZZ2
A36: GHY-LAP-0033 | C36: ="*"&A36&"*" -> *GHY-LAP-0033* | D36: Laptop | E36: Hp | F36: 15S | G36: NA | H36: IT | L36: Guwahati | M36: 5CD2100Y91 | N36: May 03, 2022 | O36: May 02, 2023
A37: GHY-LAP-0034 | C37: ="*"&A37&"*" -> *GHY-LAP-0034* | D37: Laptop | E37: Dell | F37: Optiplex 3000 | G37: CPLY921 | H37: Neeraj Kumar | I37: Production | J37: SHIFT IN-CHARGE | L37: Guwahati | M37: 1XHJ8Y3
A38: GHY-LAP-0035 | C38: ="*"&A38&"*" -> *GHY-LAP-0035* | D38: Laptop | E38: Dell | F38: Latitute3450 | G38: PTI51 | H38: Amit Kumar Singh | I38: Store | J38: STORE ASSTT. | L38: Guwahati | M38: 1NTTY32
A39: GHY-LAP-0036 | C39: ="*"&A39&"*" -> *GHY-LAP-0036* | D39: Laptop | E39: HP | F39: 240 G4 | G39: NA | H39: IT | L39: Guwahati | M39: 5CG5492LFJ
A40: GHY-LAP-0037 | C40: ="*"&A40&"*" -> *GHY-LAP-0037* | D40: Laptop | E40: Lenovo | F40: E14 | G40: CPLY1016 | H40: Aswini Kumar Nayak | I40: HR | J40: Plant HR Head | L40: Guwahati | M40: PG05E2JY | N40: 46160 | O40: 47255
A41: DeskTop
...
